<?xml version="1.0" encoding="UTF-8"?>
<!-- Generated by org.testng.reporters.JUnitReportReporter -->
<testsuite hostname="JACOBPHILLIP" name="Test_7" tests="40" failures="6" timestamp="20 Jul 2016 03:02:10 GMT" time="0.019" errors="10">
  <testcase name="testIsEmpty" time="0.000" classname="Test_7">
    <failure type="java.lang.AssertionError" message="expected [true] but found [false]">
      <![CDATA[java.lang.AssertionError: expected [true] but found [false]
	at org.testng.Assert.fail(Assert.java:94)
	at org.testng.Assert.failNotEquals(Assert.java:513)
	at org.testng.Assert.assertEqualsImpl(Assert.java:135)
	at org.testng.Assert.assertEquals(Assert.java:116)
	at org.testng.Assert.assertEquals(Assert.java:305)
	at org.testng.Assert.assertEquals(Assert.java:315)
	at TestCase.isEmpty(TestCase.java:138)
	at Test_7.testIsEmpty(Test_7.java:126)
	at sun.reflect.NativeMethodAccessorImpl.invoke0(Native Method)
	at sun.reflect.NativeMethodAccessorImpl.invoke(Unknown Source)
	at sun.reflect.DelegatingMethodAccessorImpl.invoke(Unknown Source)
	at java.lang.reflect.Method.invoke(Unknown Source)
	at org.testng.internal.MethodInvocationHelper.invokeMethod(MethodInvocationHelper.java:86)
	at org.testng.internal.Invoker.invokeMethod(Invoker.java:646)
	at org.testng.internal.Invoker.invokeTestMethod(Invoker.java:823)
	at org.testng.internal.Invoker.invokeTestMethods(Invoker.java:1131)
	at org.testng.internal.TestMethodWorker.invokeTestMethods(TestMethodWorker.java:129)
	at org.testng.internal.TestMethodWorker.run(TestMethodWorker.java:112)
	at org.testng.TestRunner.privateRun(TestRunner.java:778)
	at org.testng.TestRunner.run(TestRunner.java:632)
	at org.testng.SuiteRunner.runTest(SuiteRunner.java:366)
	at org.testng.SuiteRunner.runSequentially(SuiteRunner.java:361)
	at org.testng.SuiteRunner.privateRun(SuiteRunner.java:319)
	at org.testng.SuiteRunner.run(SuiteRunner.java:268)
	at org.testng.SuiteRunnerWorker.runSuite(SuiteRunnerWorker.java:52)
	at org.testng.SuiteRunnerWorker.run(SuiteRunnerWorker.java:86)
	at org.testng.TestNG.runSuitesSequentially(TestNG.java:1225)
	at org.testng.TestNG.runSuitesLocally(TestNG.java:1150)
	at org.testng.TestNG.runSuites(TestNG.java:1075)
	at org.testng.TestNG.run(TestNG.java:1047)
	at org.testng.remote.AbstractRemoteTestNG.run(AbstractRemoteTestNG.java:126)
	at org.testng.remote.RemoteTestNG.initAndRun(RemoteTestNG.java:137)
	at org.testng.remote.RemoteTestNG.main(RemoteTestNG.java:58)
]]>
    </failure>
  </testcase> <!-- testIsEmpty -->
  <testcase name="testAdd_validIndex" time="0.000" classname="Test_7"/>
  <testcase name="testContains_invalidElement" time="0.000" classname="Test_7"/>
  <testcase name="testRemoveFirst" time="0.000" classname="Test_7">
    <error type="org.testng.TestException" message="
Method Test_7.testRemoveFirst()[pri:0, instance:Test_7@68be2bc2] should have thrown an exception of type class java.lang.IllegalStateException">
      <![CDATA[org.testng.TestException: 
Method Test_7.testRemoveFirst()[pri:0, instance:Test_7@68be2bc2] should have thrown an exception of type class java.lang.IllegalStateException
	at org.testng.internal.ExpectedExceptionsHolder.noException(ExpectedExceptionsHolder.java:89)
	at org.testng.internal.Invoker.handleInvocationResults(Invoker.java:1350)
	at org.testng.internal.Invoker.invokeMethod(Invoker.java:684)
	at org.testng.internal.Invoker.invokeTestMethod(Invoker.java:823)
	at org.testng.internal.Invoker.invokeTestMethods(Invoker.java:1131)
	at org.testng.internal.TestMethodWorker.invokeTestMethods(TestMethodWorker.java:129)
	at org.testng.internal.TestMethodWorker.run(TestMethodWorker.java:112)
	at org.testng.TestRunner.privateRun(TestRunner.java:778)
	at org.testng.TestRunner.run(TestRunner.java:632)
	at org.testng.SuiteRunner.runTest(SuiteRunner.java:366)
	at org.testng.SuiteRunner.runSequentially(SuiteRunner.java:361)
	at org.testng.SuiteRunner.privateRun(SuiteRunner.java:319)
	at org.testng.SuiteRunner.run(SuiteRunner.java:268)
	at org.testng.SuiteRunnerWorker.runSuite(SuiteRunnerWorker.java:52)
	at org.testng.SuiteRunnerWorker.run(SuiteRunnerWorker.java:86)
	at org.testng.TestNG.runSuitesSequentially(TestNG.java:1225)
	at org.testng.TestNG.runSuitesLocally(TestNG.java:1150)
	at org.testng.TestNG.runSuites(TestNG.java:1075)
	at org.testng.TestNG.run(TestNG.java:1047)
	at org.testng.remote.AbstractRemoteTestNG.run(AbstractRemoteTestNG.java:126)
	at org.testng.remote.RemoteTestNG.initAndRun(RemoteTestNG.java:137)
	at org.testng.remote.RemoteTestNG.main(RemoteTestNG.java:58)
]]>
    </error>
  </testcase> <!-- testRemoveFirst -->
  <testcase name="testAdd_validIndex" time="0.001" classname="Test_7"/>
  <testcase name="testRemove_invalidIndex" time="0.000" classname="Test_7"/>
  <testcase name="testFirst" time="0.001" classname="Test_7"/>
  <testcase name="testSet" time="0.000" classname="Test_7"/>
  <testcase name="testIterator" time="0.001" classname="Test_7">
    <error type="java.lang.UnsupportedOperationException">
      <![CDATA[java.lang.UnsupportedOperationException
	at Test_7.testIterator(Test_7.java:147)
	at sun.reflect.NativeMethodAccessorImpl.invoke0(Native Method)
	at sun.reflect.NativeMethodAccessorImpl.invoke(Unknown Source)
	at sun.reflect.DelegatingMethodAccessorImpl.invoke(Unknown Source)
	at java.lang.reflect.Method.invoke(Unknown Source)
	at org.testng.internal.MethodInvocationHelper.invokeMethod(MethodInvocationHelper.java:86)
	at org.testng.internal.Invoker.invokeMethod(Invoker.java:646)
	at org.testng.internal.Invoker.invokeTestMethod(Invoker.java:823)
	at org.testng.internal.Invoker.invokeTestMethods(Invoker.java:1131)
	at org.testng.internal.TestMethodWorker.invokeTestMethods(TestMethodWorker.java:129)
	at org.testng.internal.TestMethodWorker.run(TestMethodWorker.java:112)
	at org.testng.TestRunner.privateRun(TestRunner.java:778)
	at org.testng.TestRunner.run(TestRunner.java:632)
	at org.testng.SuiteRunner.runTest(SuiteRunner.java:366)
	at org.testng.SuiteRunner.runSequentially(SuiteRunner.java:361)
	at org.testng.SuiteRunner.privateRun(SuiteRunner.java:319)
	at org.testng.SuiteRunner.run(SuiteRunner.java:268)
	at org.testng.SuiteRunnerWorker.runSuite(SuiteRunnerWorker.java:52)
	at org.testng.SuiteRunnerWorker.run(SuiteRunnerWorker.java:86)
	at org.testng.TestNG.runSuitesSequentially(TestNG.java:1225)
	at org.testng.TestNG.runSuitesLocally(TestNG.java:1150)
	at org.testng.TestNG.runSuites(TestNG.java:1075)
	at org.testng.TestNG.run(TestNG.java:1047)
	at org.testng.remote.AbstractRemoteTestNG.run(AbstractRemoteTestNG.java:126)
	at org.testng.remote.RemoteTestNG.initAndRun(RemoteTestNG.java:137)
	at org.testng.remote.RemoteTestNG.main(RemoteTestNG.java:58)
]]>
    </error>
  </testcase> <!-- testIterator -->
  <testcase name="testGet" time="0.001" classname="Test_7"/>
  <testcase name="testAddToFront" time="0.000" classname="Test_7"/>
  <testcase name="testAddToFront" time="0.003" classname="Test_7"/>
  <testcase name="testRemoveLast" time="0.000" classname="Test_7"/>
  <testcase name="testIndexOf_invalidElement" time="0.000" classname="Test_7">
    <failure type="java.lang.AssertionError" message="expected [-1] but found [0]">
      <![CDATA[java.lang.AssertionError: expected [-1] but found [0]
	at org.testng.Assert.fail(Assert.java:94)
	at org.testng.Assert.failNotEquals(Assert.java:513)
	at org.testng.Assert.assertEqualsImpl(Assert.java:135)
	at org.testng.Assert.assertEquals(Assert.java:116)
	at org.testng.Assert.assertEquals(Assert.java:389)
	at org.testng.Assert.assertEquals(Assert.java:399)
	at TestCase.indexOf(TestCase.java:227)
	at Test_7.testIndexOf_invalidElement(Test_7.java:249)
	at sun.reflect.NativeMethodAccessorImpl.invoke0(Native Method)
	at sun.reflect.NativeMethodAccessorImpl.invoke(Unknown Source)
	at sun.reflect.DelegatingMethodAccessorImpl.invoke(Unknown Source)
	at java.lang.reflect.Method.invoke(Unknown Source)
	at org.testng.internal.MethodInvocationHelper.invokeMethod(MethodInvocationHelper.java:86)
	at org.testng.internal.Invoker.invokeMethod(Invoker.java:646)
	at org.testng.internal.Invoker.invokeTestMethod(Invoker.java:823)
	at org.testng.internal.Invoker.invokeTestMethods(Invoker.java:1131)
	at org.testng.internal.TestMethodWorker.invokeTestMethods(TestMethodWorker.java:129)
	at org.testng.internal.TestMethodWorker.run(TestMethodWorker.java:112)
	at org.testng.TestRunner.privateRun(TestRunner.java:778)
	at org.testng.TestRunner.run(TestRunner.java:632)
	at org.testng.SuiteRunner.runTest(SuiteRunner.java:366)
	at org.testng.SuiteRunner.runSequentially(SuiteRunner.java:361)
	at org.testng.SuiteRunner.privateRun(SuiteRunner.java:319)
	at org.testng.SuiteRunner.run(SuiteRunner.java:268)
	at org.testng.SuiteRunnerWorker.runSuite(SuiteRunnerWorker.java:52)
	at org.testng.SuiteRunnerWorker.run(SuiteRunnerWorker.java:86)
	at org.testng.TestNG.runSuitesSequentially(TestNG.java:1225)
	at org.testng.TestNG.runSuitesLocally(TestNG.java:1150)
	at org.testng.TestNG.runSuites(TestNG.java:1075)
	at org.testng.TestNG.run(TestNG.java:1047)
	at org.testng.remote.AbstractRemoteTestNG.run(AbstractRemoteTestNG.java:126)
	at org.testng.remote.RemoteTestNG.initAndRun(RemoteTestNG.java:137)
	at org.testng.remote.RemoteTestNG.main(RemoteTestNG.java:58)
]]>
    </failure>
  </testcase> <!-- testIndexOf_invalidElement -->
  <testcase name="testRemove_invalidElement" time="0.001" classname="Test_7">
    <failure type="java.lang.AssertionError" message="expected [6] but found [null]">
      <![CDATA[java.lang.AssertionError: expected [6] but found [null]
	at org.testng.Assert.fail(Assert.java:94)
	at org.testng.Assert.failNotEquals(Assert.java:513)
	at org.testng.Assert.assertEqualsImpl(Assert.java:130)
	at org.testng.Assert.assertEquals(Assert.java:116)
	at org.testng.Assert.assertEquals(Assert.java:179)
	at TestCase.remove(TestCase.java:93)
	at Test_7.testRemove_invalidElement(Test_7.java:86)
	at sun.reflect.NativeMethodAccessorImpl.invoke0(Native Method)
	at sun.reflect.NativeMethodAccessorImpl.invoke(Unknown Source)
	at sun.reflect.DelegatingMethodAccessorImpl.invoke(Unknown Source)
	at java.lang.reflect.Method.invoke(Unknown Source)
	at org.testng.internal.MethodInvocationHelper.invokeMethod(MethodInvocationHelper.java:86)
	at org.testng.internal.Invoker.invokeMethod(Invoker.java:646)
	at org.testng.internal.Invoker.invokeTestMethod(Invoker.java:823)
	at org.testng.internal.Invoker.invokeTestMethods(Invoker.java:1131)
	at org.testng.internal.TestMethodWorker.invokeTestMethods(TestMethodWorker.java:129)
	at org.testng.internal.TestMethodWorker.run(TestMethodWorker.java:112)
	at org.testng.TestRunner.privateRun(TestRunner.java:778)
	at org.testng.TestRunner.run(TestRunner.java:632)
	at org.testng.SuiteRunner.runTest(SuiteRunner.java:366)
	at org.testng.SuiteRunner.runSequentially(SuiteRunner.java:361)
	at org.testng.SuiteRunner.privateRun(SuiteRunner.java:319)
	at org.testng.SuiteRunner.run(SuiteRunner.java:268)
	at org.testng.SuiteRunnerWorker.runSuite(SuiteRunnerWorker.java:52)
	at org.testng.SuiteRunnerWorker.run(SuiteRunnerWorker.java:86)
	at org.testng.TestNG.runSuitesSequentially(TestNG.java:1225)
	at org.testng.TestNG.runSuitesLocally(TestNG.java:1150)
	at org.testng.TestNG.runSuites(TestNG.java:1075)
	at org.testng.TestNG.run(TestNG.java:1047)
	at org.testng.remote.AbstractRemoteTestNG.run(AbstractRemoteTestNG.java:126)
	at org.testng.remote.RemoteTestNG.initAndRun(RemoteTestNG.java:137)
	at org.testng.remote.RemoteTestNG.main(RemoteTestNG.java:58)
]]>
    </failure>
  </testcase> <!-- testRemove_invalidElement -->
  <testcase name="testContains_invalidElement" time="0.000" classname="Test_7"/>
  <testcase name="testAdd" time="0.000" classname="Test_7"/>
  <testcase name="testAdd" time="0.000" classname="Test_7"/>
  <testcase name="testAdd_invalidIndex" time="0.000" classname="Test_7">
    <error type="org.testng.TestException" message="
Method Test_7.testAdd_invalidIndex(int)[pri:0, instance:Test_7@68be2bc2] should have thrown an exception of type class java.lang.IndexOutOfBoundsException">
      <![CDATA[org.testng.TestException: 
Method Test_7.testAdd_invalidIndex(int)[pri:0, instance:Test_7@68be2bc2] should have thrown an exception of type class java.lang.IndexOutOfBoundsException
	at org.testng.internal.ExpectedExceptionsHolder.noException(ExpectedExceptionsHolder.java:89)
	at org.testng.internal.Invoker.handleInvocationResults(Invoker.java:1350)
	at org.testng.internal.Invoker.invokeMethod(Invoker.java:684)
	at org.testng.internal.Invoker.invokeTestMethod(Invoker.java:823)
	at org.testng.internal.Invoker.invokeTestMethods(Invoker.java:1131)
	at org.testng.internal.TestMethodWorker.invokeTestMethods(TestMethodWorker.java:129)
	at org.testng.internal.TestMethodWorker.run(TestMethodWorker.java:112)
	at org.testng.TestRunner.privateRun(TestRunner.java:778)
	at org.testng.TestRunner.run(TestRunner.java:632)
	at org.testng.SuiteRunner.runTest(SuiteRunner.java:366)
	at org.testng.SuiteRunner.runSequentially(SuiteRunner.java:361)
	at org.testng.SuiteRunner.privateRun(SuiteRunner.java:319)
	at org.testng.SuiteRunner.run(SuiteRunner.java:268)
	at org.testng.SuiteRunnerWorker.runSuite(SuiteRunnerWorker.java:52)
	at org.testng.SuiteRunnerWorker.run(SuiteRunnerWorker.java:86)
	at org.testng.TestNG.runSuitesSequentially(TestNG.java:1225)
	at org.testng.TestNG.runSuitesLocally(TestNG.java:1150)
	at org.testng.TestNG.runSuites(TestNG.java:1075)
	at org.testng.TestNG.run(TestNG.java:1047)
	at org.testng.remote.AbstractRemoteTestNG.run(AbstractRemoteTestNG.java:126)
	at org.testng.remote.RemoteTestNG.initAndRun(RemoteTestNG.java:137)
	at org.testng.remote.RemoteTestNG.main(RemoteTestNG.java:58)
]]>
    </error>
  </testcase> <!-- testAdd_invalidIndex -->
  <testcase name="testAddToRear" time="0.000" classname="Test_7"/>
  <testcase name="testSet" time="0.000" classname="Test_7">
    <error type="org.testng.TestException" message="
Method Test_7.testSet()[pri:0, instance:Test_7@68be2bc2] should have thrown an exception of type class java.lang.IndexOutOfBoundsException">
      <![CDATA[org.testng.TestException: 
Method Test_7.testSet()[pri:0, instance:Test_7@68be2bc2] should have thrown an exception of type class java.lang.IndexOutOfBoundsException
	at org.testng.internal.ExpectedExceptionsHolder.noException(ExpectedExceptionsHolder.java:89)
	at org.testng.internal.Invoker.handleInvocationResults(Invoker.java:1350)
	at org.testng.internal.Invoker.invokeMethod(Invoker.java:684)
	at org.testng.internal.Invoker.invokeTestMethod(Invoker.java:823)
	at org.testng.internal.Invoker.invokeTestMethods(Invoker.java:1131)
	at org.testng.internal.TestMethodWorker.invokeTestMethods(TestMethodWorker.java:129)
	at org.testng.internal.TestMethodWorker.run(TestMethodWorker.java:112)
	at org.testng.TestRunner.privateRun(TestRunner.java:778)
	at org.testng.TestRunner.run(TestRunner.java:632)
	at org.testng.SuiteRunner.runTest(SuiteRunner.java:366)
	at org.testng.SuiteRunner.runSequentially(SuiteRunner.java:361)
	at org.testng.SuiteRunner.privateRun(SuiteRunner.java:319)
	at org.testng.SuiteRunner.run(SuiteRunner.java:268)
	at org.testng.SuiteRunnerWorker.runSuite(SuiteRunnerWorker.java:52)
	at org.testng.SuiteRunnerWorker.run(SuiteRunnerWorker.java:86)
	at org.testng.TestNG.runSuitesSequentially(TestNG.java:1225)
	at org.testng.TestNG.runSuitesLocally(TestNG.java:1150)
	at org.testng.TestNG.runSuites(TestNG.java:1075)
	at org.testng.TestNG.run(TestNG.java:1047)
	at org.testng.remote.AbstractRemoteTestNG.run(AbstractRemoteTestNG.java:126)
	at org.testng.remote.RemoteTestNG.initAndRun(RemoteTestNG.java:137)
	at org.testng.remote.RemoteTestNG.main(RemoteTestNG.java:58)
]]>
    </error>
  </testcase> <!-- testSet -->
  <testcase name="testAdd_invalidIndex" time="0.000" classname="Test_7">
    <error type="org.testng.TestException" message="
Method Test_7.testAdd_invalidIndex(int)[pri:0, instance:Test_7@68be2bc2] should have thrown an exception of type class java.lang.IndexOutOfBoundsException">
      <![CDATA[org.testng.TestException: 
Method Test_7.testAdd_invalidIndex(int)[pri:0, instance:Test_7@68be2bc2] should have thrown an exception of type class java.lang.IndexOutOfBoundsException
	at org.testng.internal.ExpectedExceptionsHolder.noException(ExpectedExceptionsHolder.java:89)
	at org.testng.internal.Invoker.handleInvocationResults(Invoker.java:1350)
	at org.testng.internal.Invoker.invokeMethod(Invoker.java:684)
	at org.testng.internal.Invoker.invokeTestMethod(Invoker.java:823)
	at org.testng.internal.Invoker.invokeTestMethods(Invoker.java:1131)
	at org.testng.internal.TestMethodWorker.invokeTestMethods(TestMethodWorker.java:129)
	at org.testng.internal.TestMethodWorker.run(TestMethodWorker.java:112)
	at org.testng.TestRunner.privateRun(TestRunner.java:778)
	at org.testng.TestRunner.run(TestRunner.java:632)
	at org.testng.SuiteRunner.runTest(SuiteRunner.java:366)
	at org.testng.SuiteRunner.runSequentially(SuiteRunner.java:361)
	at org.testng.SuiteRunner.privateRun(SuiteRunner.java:319)
	at org.testng.SuiteRunner.run(SuiteRunner.java:268)
	at org.testng.SuiteRunnerWorker.runSuite(SuiteRunnerWorker.java:52)
	at org.testng.SuiteRunnerWorker.run(SuiteRunnerWorker.java:86)
	at org.testng.TestNG.runSuitesSequentially(TestNG.java:1225)
	at org.testng.TestNG.runSuitesLocally(TestNG.java:1150)
	at org.testng.TestNG.runSuites(TestNG.java:1075)
	at org.testng.TestNG.run(TestNG.java:1047)
	at org.testng.remote.AbstractRemoteTestNG.run(AbstractRemoteTestNG.java:126)
	at org.testng.remote.RemoteTestNG.initAndRun(RemoteTestNG.java:137)
	at org.testng.remote.RemoteTestNG.main(RemoteTestNG.java:58)
]]>
    </error>
  </testcase> <!-- testAdd_invalidIndex -->
  <testcase name="testSize" time="0.001" classname="Test_7"/>
  <testcase name="testAddToRear" time="0.002" classname="Test_7"/>
  <testcase name="testLast" time="0.000" classname="Test_7">
    <error type="org.testng.TestException" message="
Method Test_7.testLast()[pri:0, instance:Test_7@68be2bc2] should have thrown an exception of type class java.lang.IllegalStateException">
      <![CDATA[org.testng.TestException: 
Method Test_7.testLast()[pri:0, instance:Test_7@68be2bc2] should have thrown an exception of type class java.lang.IllegalStateException
	at org.testng.internal.ExpectedExceptionsHolder.noException(ExpectedExceptionsHolder.java:89)
	at org.testng.internal.Invoker.handleInvocationResults(Invoker.java:1350)
	at org.testng.internal.Invoker.invokeMethod(Invoker.java:684)
	at org.testng.internal.Invoker.invokeTestMethod(Invoker.java:823)
	at org.testng.internal.Invoker.invokeTestMethods(Invoker.java:1131)
	at org.testng.internal.TestMethodWorker.invokeTestMethods(TestMethodWorker.java:129)
	at org.testng.internal.TestMethodWorker.run(TestMethodWorker.java:112)
	at org.testng.TestRunner.privateRun(TestRunner.java:778)
	at org.testng.TestRunner.run(TestRunner.java:632)
	at org.testng.SuiteRunner.runTest(SuiteRunner.java:366)
	at org.testng.SuiteRunner.runSequentially(SuiteRunner.java:361)
	at org.testng.SuiteRunner.privateRun(SuiteRunner.java:319)
	at org.testng.SuiteRunner.run(SuiteRunner.java:268)
	at org.testng.SuiteRunnerWorker.runSuite(SuiteRunnerWorker.java:52)
	at org.testng.SuiteRunnerWorker.run(SuiteRunnerWorker.java:86)
	at org.testng.TestNG.runSuitesSequentially(TestNG.java:1225)
	at org.testng.TestNG.runSuitesLocally(TestNG.java:1150)
	at org.testng.TestNG.runSuites(TestNG.java:1075)
	at org.testng.TestNG.run(TestNG.java:1047)
	at org.testng.remote.AbstractRemoteTestNG.run(AbstractRemoteTestNG.java:126)
	at org.testng.remote.RemoteTestNG.initAndRun(RemoteTestNG.java:137)
	at org.testng.remote.RemoteTestNG.main(RemoteTestNG.java:58)
]]>
    </error>
  </testcase> <!-- testLast -->
  <testcase name="testRemoveFirst" time="0.001" classname="Test_7"/>
  <testcase name="testIterator" time="0.000" classname="Test_7">
    <error type="java.lang.UnsupportedOperationException">
      <![CDATA[java.lang.UnsupportedOperationException
	at Test_7.testIterator(Test_7.java:147)
	at sun.reflect.NativeMethodAccessorImpl.invoke0(Native Method)
	at sun.reflect.NativeMethodAccessorImpl.invoke(Unknown Source)
	at sun.reflect.DelegatingMethodAccessorImpl.invoke(Unknown Source)
	at java.lang.reflect.Method.invoke(Unknown Source)
	at org.testng.internal.MethodInvocationHelper.invokeMethod(MethodInvocationHelper.java:86)
	at org.testng.internal.Invoker.invokeMethod(Invoker.java:646)
	at org.testng.internal.Invoker.invokeTestMethod(Invoker.java:823)
	at org.testng.internal.Invoker.invokeTestMethods(Invoker.java:1131)
	at org.testng.internal.TestMethodWorker.invokeTestMethods(TestMethodWorker.java:129)
	at org.testng.internal.TestMethodWorker.run(TestMethodWorker.java:112)
	at org.testng.TestRunner.privateRun(TestRunner.java:778)
	at org.testng.TestRunner.run(TestRunner.java:632)
	at org.testng.SuiteRunner.runTest(SuiteRunner.java:366)
	at org.testng.SuiteRunner.runSequentially(SuiteRunner.java:361)
	at org.testng.SuiteRunner.privateRun(SuiteRunner.java:319)
	at org.testng.SuiteRunner.run(SuiteRunner.java:268)
	at org.testng.SuiteRunnerWorker.runSuite(SuiteRunnerWorker.java:52)
	at org.testng.SuiteRunnerWorker.run(SuiteRunnerWorker.java:86)
	at org.testng.TestNG.runSuitesSequentially(TestNG.java:1225)
	at org.testng.TestNG.runSuitesLocally(TestNG.java:1150)
	at org.testng.TestNG.runSuites(TestNG.java:1075)
	at org.testng.TestNG.run(TestNG.java:1047)
	at org.testng.remote.AbstractRemoteTestNG.run(AbstractRemoteTestNG.java:126)
	at org.testng.remote.RemoteTestNG.initAndRun(RemoteTestNG.java:137)
	at org.testng.remote.RemoteTestNG.main(RemoteTestNG.java:58)
]]>
    </error>
  </testcase> <!-- testIterator -->
  <testcase name="testAdd_invalidIndex" time="0.000" classname="Test_7"/>
  <testcase name="testAddAfter_invalidElement" time="0.000" classname="Test_7">
    <error type="org.testng.TestException" message="
Method Test_7.testAddAfter_invalidElement()[pri:0, instance:Test_7@68be2bc2] should have thrown an exception of type class java.util.NoSuchElementException">
      <![CDATA[org.testng.TestException: 
Method Test_7.testAddAfter_invalidElement()[pri:0, instance:Test_7@68be2bc2] should have thrown an exception of type class java.util.NoSuchElementException
	at org.testng.internal.ExpectedExceptionsHolder.noException(ExpectedExceptionsHolder.java:89)
	at org.testng.internal.Invoker.handleInvocationResults(Invoker.java:1350)
	at org.testng.internal.Invoker.invokeMethod(Invoker.java:684)
	at org.testng.internal.Invoker.invokeTestMethod(Invoker.java:823)
	at org.testng.internal.Invoker.invokeTestMethods(Invoker.java:1131)
	at org.testng.internal.TestMethodWorker.invokeTestMethods(TestMethodWorker.java:129)
	at org.testng.internal.TestMethodWorker.run(TestMethodWorker.java:112)
	at org.testng.TestRunner.privateRun(TestRunner.java:778)
	at org.testng.TestRunner.run(TestRunner.java:632)
	at org.testng.SuiteRunner.runTest(SuiteRunner.java:366)
	at org.testng.SuiteRunner.runSequentially(SuiteRunner.java:361)
	at org.testng.SuiteRunner.privateRun(SuiteRunner.java:319)
	at org.testng.SuiteRunner.run(SuiteRunner.java:268)
	at org.testng.SuiteRunnerWorker.runSuite(SuiteRunnerWorker.java:52)
	at org.testng.SuiteRunnerWorker.run(SuiteRunnerWorker.java:86)
	at org.testng.TestNG.runSuitesSequentially(TestNG.java:1225)
	at org.testng.TestNG.runSuitesLocally(TestNG.java:1150)
	at org.testng.TestNG.runSuites(TestNG.java:1075)
	at org.testng.TestNG.run(TestNG.java:1047)
	at org.testng.remote.AbstractRemoteTestNG.run(AbstractRemoteTestNG.java:126)
	at org.testng.remote.RemoteTestNG.initAndRun(RemoteTestNG.java:137)
	at org.testng.remote.RemoteTestNG.main(RemoteTestNG.java:58)
]]>
    </error>
  </testcase> <!-- testAddAfter_invalidElement -->
  <testcase name="testIndexOf_invalidElement" time="0.001" classname="Test_7"/>
  <testcase name="testAddAfter_invalidElement" time="0.000" classname="Test_7"/>
  <testcase name="testRemove_invalidElement" time="0.000" classname="Test_7"/>
  <testcase name="testFirst" time="0.001" classname="Test_7">
    <error type="org.testng.TestException" message="
Method Test_7.testFirst()[pri:0, instance:Test_7@68be2bc2] should have thrown an exception of type class java.lang.IllegalStateException">
      <![CDATA[org.testng.TestException: 
Method Test_7.testFirst()[pri:0, instance:Test_7@68be2bc2] should have thrown an exception of type class java.lang.IllegalStateException
	at org.testng.internal.ExpectedExceptionsHolder.noException(ExpectedExceptionsHolder.java:89)
	at org.testng.internal.Invoker.handleInvocationResults(Invoker.java:1350)
	at org.testng.internal.Invoker.invokeMethod(Invoker.java:684)
	at org.testng.internal.Invoker.invokeTestMethod(Invoker.java:823)
	at org.testng.internal.Invoker.invokeTestMethods(Invoker.java:1131)
	at org.testng.internal.TestMethodWorker.invokeTestMethods(TestMethodWorker.java:129)
	at org.testng.internal.TestMethodWorker.run(TestMethodWorker.java:112)
	at org.testng.TestRunner.privateRun(TestRunner.java:778)
	at org.testng.TestRunner.run(TestRunner.java:632)
	at org.testng.SuiteRunner.runTest(SuiteRunner.java:366)
	at org.testng.SuiteRunner.runSequentially(SuiteRunner.java:361)
	at org.testng.SuiteRunner.privateRun(SuiteRunner.java:319)
	at org.testng.SuiteRunner.run(SuiteRunner.java:268)
	at org.testng.SuiteRunnerWorker.runSuite(SuiteRunnerWorker.java:52)
	at org.testng.SuiteRunnerWorker.run(SuiteRunnerWorker.java:86)
	at org.testng.TestNG.runSuitesSequentially(TestNG.java:1225)
	at org.testng.TestNG.runSuitesLocally(TestNG.java:1150)
	at org.testng.TestNG.runSuites(TestNG.java:1075)
	at org.testng.TestNG.run(TestNG.java:1047)
	at org.testng.remote.AbstractRemoteTestNG.run(AbstractRemoteTestNG.java:126)
	at org.testng.remote.RemoteTestNG.initAndRun(RemoteTestNG.java:137)
	at org.testng.remote.RemoteTestNG.main(RemoteTestNG.java:58)
]]>
    </error>
  </testcase> <!-- testFirst -->
  <testcase name="testAdd_invalidIndex" time="0.000" classname="Test_7"/>
  <testcase name="testGet" time="0.000" classname="Test_7">
    <failure type="java.lang.AssertionError" message="expected [5] but found [null]">
      <![CDATA[java.lang.AssertionError: expected [5] but found [null]
	at org.testng.Assert.fail(Assert.java:94)
	at org.testng.Assert.failNotEquals(Assert.java:513)
	at org.testng.Assert.assertEqualsImpl(Assert.java:130)
	at org.testng.Assert.assertEquals(Assert.java:116)
	at org.testng.Assert.assertEquals(Assert.java:179)
	at TestCase.get(TestCase.java:215)
	at Test_7.testGet(Test_7.java:239)
	at sun.reflect.NativeMethodAccessorImpl.invoke0(Native Method)
	at sun.reflect.NativeMethodAccessorImpl.invoke(Unknown Source)
	at sun.reflect.DelegatingMethodAccessorImpl.invoke(Unknown Source)
	at java.lang.reflect.Method.invoke(Unknown Source)
	at org.testng.internal.MethodInvocationHelper.invokeMethod(MethodInvocationHelper.java:86)
	at org.testng.internal.Invoker.invokeMethod(Invoker.java:646)
	at org.testng.internal.Invoker.invokeTestMethod(Invoker.java:823)
	at org.testng.internal.Invoker.invokeTestMethods(Invoker.java:1131)
	at org.testng.internal.TestMethodWorker.invokeTestMethods(TestMethodWorker.java:129)
	at org.testng.internal.TestMethodWorker.run(TestMethodWorker.java:112)
	at org.testng.TestRunner.privateRun(TestRunner.java:778)
	at org.testng.TestRunner.run(TestRunner.java:632)
	at org.testng.SuiteRunner.runTest(SuiteRunner.java:366)
	at org.testng.SuiteRunner.runSequentially(SuiteRunner.java:361)
	at org.testng.SuiteRunner.privateRun(SuiteRunner.java:319)
	at org.testng.SuiteRunner.run(SuiteRunner.java:268)
	at org.testng.SuiteRunnerWorker.runSuite(SuiteRunnerWorker.java:52)
	at org.testng.SuiteRunnerWorker.run(SuiteRunnerWorker.java:86)
	at org.testng.TestNG.runSuitesSequentially(TestNG.java:1225)
	at org.testng.TestNG.runSuitesLocally(TestNG.java:1150)
	at org.testng.TestNG.runSuites(TestNG.java:1075)
	at org.testng.TestNG.run(TestNG.java:1047)
	at org.testng.remote.AbstractRemoteTestNG.run(AbstractRemoteTestNG.java:126)
	at org.testng.remote.RemoteTestNG.initAndRun(RemoteTestNG.java:137)
	at org.testng.remote.RemoteTestNG.main(RemoteTestNG.java:58)
]]>
    </failure>
  </testcase> <!-- testGet -->
  <testcase name="testRemove_invalidIndex" time="0.000" classname="Test_7">
    <failure type="java.lang.AssertionError" message="expected [5] but found [null]">
      <![CDATA[java.lang.AssertionError: expected [5] but found [null]
	at org.testng.Assert.fail(Assert.java:94)
	at org.testng.Assert.failNotEquals(Assert.java:513)
	at org.testng.Assert.assertEqualsImpl(Assert.java:130)
	at org.testng.Assert.assertEquals(Assert.java:116)
	at org.testng.Assert.assertEquals(Assert.java:179)
	at TestCase.remove(TestCase.java:182)
	at Test_7.testRemove_invalidIndex(Test_7.java:207)
	at sun.reflect.NativeMethodAccessorImpl.invoke0(Native Method)
	at sun.reflect.NativeMethodAccessorImpl.invoke(Unknown Source)
	at sun.reflect.DelegatingMethodAccessorImpl.invoke(Unknown Source)
	at java.lang.reflect.Method.invoke(Unknown Source)
	at org.testng.internal.MethodInvocationHelper.invokeMethod(MethodInvocationHelper.java:86)
	at org.testng.internal.Invoker.invokeMethod(Invoker.java:646)
	at org.testng.internal.Invoker.invokeTestMethod(Invoker.java:823)
	at org.testng.internal.Invoker.invokeTestMethods(Invoker.java:1131)
	at org.testng.internal.TestMethodWorker.invokeTestMethods(TestMethodWorker.java:129)
	at org.testng.internal.TestMethodWorker.run(TestMethodWorker.java:112)
	at org.testng.TestRunner.privateRun(TestRunner.java:778)
	at org.testng.TestRunner.run(TestRunner.java:632)
	at org.testng.SuiteRunner.runTest(SuiteRunner.java:366)
	at org.testng.SuiteRunner.runSequentially(SuiteRunner.java:361)
	at org.testng.SuiteRunner.privateRun(SuiteRunner.java:319)
	at org.testng.SuiteRunner.run(SuiteRunner.java:268)
	at org.testng.SuiteRunnerWorker.runSuite(SuiteRunnerWorker.java:52)
	at org.testng.SuiteRunnerWorker.run(SuiteRunnerWorker.java:86)
	at org.testng.TestNG.runSuitesSequentially(TestNG.java:1225)
	at org.testng.TestNG.runSuitesLocally(TestNG.java:1150)
	at org.testng.TestNG.runSuites(TestNG.java:1075)
	at org.testng.TestNG.run(TestNG.java:1047)
	at org.testng.remote.AbstractRemoteTestNG.run(AbstractRemoteTestNG.java:126)
	at org.testng.remote.RemoteTestNG.initAndRun(RemoteTestNG.java:137)
	at org.testng.remote.RemoteTestNG.main(RemoteTestNG.java:58)
]]>
    </failure>
  </testcase> <!-- testRemove_invalidIndex -->
  <testcase name="testLast" time="0.001" classname="Test_7"/>
  <testcase name="testRemoveLast" time="0.003" classname="Test_7">
    <error type="org.testng.TestException" message="
Method Test_7.testRemoveLast()[pri:0, instance:Test_7@68be2bc2] should have thrown an exception of type class java.lang.IllegalStateException">
      <![CDATA[org.testng.TestException: 
Method Test_7.testRemoveLast()[pri:0, instance:Test_7@68be2bc2] should have thrown an exception of type class java.lang.IllegalStateException
	at org.testng.internal.ExpectedExceptionsHolder.noException(ExpectedExceptionsHolder.java:89)
	at org.testng.internal.Invoker.handleInvocationResults(Invoker.java:1350)
	at org.testng.internal.Invoker.invokeMethod(Invoker.java:684)
	at org.testng.internal.Invoker.invokeTestMethod(Invoker.java:823)
	at org.testng.internal.Invoker.invokeTestMethods(Invoker.java:1131)
	at org.testng.internal.TestMethodWorker.invokeTestMethods(TestMethodWorker.java:129)
	at org.testng.internal.TestMethodWorker.run(TestMethodWorker.java:112)
	at org.testng.TestRunner.privateRun(TestRunner.java:778)
	at org.testng.TestRunner.run(TestRunner.java:632)
	at org.testng.SuiteRunner.runTest(SuiteRunner.java:366)
	at org.testng.SuiteRunner.runSequentially(SuiteRunner.java:361)
	at org.testng.SuiteRunner.privateRun(SuiteRunner.java:319)
	at org.testng.SuiteRunner.run(SuiteRunner.java:268)
	at org.testng.SuiteRunnerWorker.runSuite(SuiteRunnerWorker.java:52)
	at org.testng.SuiteRunnerWorker.run(SuiteRunnerWorker.java:86)
	at org.testng.TestNG.runSuitesSequentially(TestNG.java:1225)
	at org.testng.TestNG.runSuitesLocally(TestNG.java:1150)
	at org.testng.TestNG.runSuites(TestNG.java:1075)
	at org.testng.TestNG.run(TestNG.java:1047)
	at org.testng.remote.AbstractRemoteTestNG.run(AbstractRemoteTestNG.java:126)
	at org.testng.remote.RemoteTestNG.initAndRun(RemoteTestNG.java:137)
	at org.testng.remote.RemoteTestNG.main(RemoteTestNG.java:58)
]]>
    </error>
  </testcase> <!-- testRemoveLast -->
  <testcase name="testSize" time="0.000" classname="Test_7">
    <failure type="java.lang.AssertionError" message="expected [0] but found [-1]">
      <![CDATA[java.lang.AssertionError: expected [0] but found [-1]
	at org.testng.Assert.fail(Assert.java:94)
	at org.testng.Assert.failNotEquals(Assert.java:513)
	at org.testng.Assert.assertEqualsImpl(Assert.java:135)
	at org.testng.Assert.assertEquals(Assert.java:116)
	at org.testng.Assert.assertEquals(Assert.java:389)
	at org.testng.Assert.assertEquals(Assert.java:399)
	at TestCase.size(TestCase.java:149)
	at Test_7.testSize(Test_7.java:136)
	at sun.reflect.NativeMethodAccessorImpl.invoke0(Native Method)
	at sun.reflect.NativeMethodAccessorImpl.invoke(Unknown Source)
	at sun.reflect.DelegatingMethodAccessorImpl.invoke(Unknown Source)
	at java.lang.reflect.Method.invoke(Unknown Source)
	at org.testng.internal.MethodInvocationHelper.invokeMethod(MethodInvocationHelper.java:86)
	at org.testng.internal.Invoker.invokeMethod(Invoker.java:646)
	at org.testng.internal.Invoker.invokeTestMethod(Invoker.java:823)
	at org.testng.internal.Invoker.invokeTestMethods(Invoker.java:1131)
	at org.testng.internal.TestMethodWorker.invokeTestMethods(TestMethodWorker.java:129)
	at org.testng.internal.TestMethodWorker.run(TestMethodWorker.java:112)
	at org.testng.TestRunner.privateRun(TestRunner.java:778)
	at org.testng.TestRunner.run(TestRunner.java:632)
	at org.testng.SuiteRunner.runTest(SuiteRunner.java:366)
	at org.testng.SuiteRunner.runSequentially(SuiteRunner.java:361)
	at org.testng.SuiteRunner.privateRun(SuiteRunner.java:319)
	at org.testng.SuiteRunner.run(SuiteRunner.java:268)
	at org.testng.SuiteRunnerWorker.runSuite(SuiteRunnerWorker.java:52)
	at org.testng.SuiteRunnerWorker.run(SuiteRunnerWorker.java:86)
	at org.testng.TestNG.runSuitesSequentially(TestNG.java:1225)
	at org.testng.TestNG.runSuitesLocally(TestNG.java:1150)
	at org.testng.TestNG.runSuites(TestNG.java:1075)
	at org.testng.TestNG.run(TestNG.java:1047)
	at org.testng.remote.AbstractRemoteTestNG.run(AbstractRemoteTestNG.java:126)
	at org.testng.remote.RemoteTestNG.initAndRun(RemoteTestNG.java:137)
	at org.testng.remote.RemoteTestNG.main(RemoteTestNG.java:58)
]]>
    </failure>
  </testcase> <!-- testSize -->
  <testcase name="testIsEmpty" time="0.001" classname="Test_7"/>
</testsuite> <!-- Test_7 -->
